<?xml version="1.0"?>
<robot name="os_robots" xmlns:xacro="http://ros.org/wiki/xacro">

<link name="base_footprint">
    <visual>
        <origin xyz="0 0 0" rpy="0 -0 0"/>
        <geometry>
            <box size="0.001 0.001 0.001" />
        </geometry>
    </visual>
</link>

<joint name="base_footprint_joint" type="fixed">
    <origin xyz="0 0 0" rpy="0 0 0" />
    <parent link="base_footprint"/>
    <child link="base" />
</joint>

<link name="base">
<visual>
<origin xyz="0 0 0" rpy="0 -0 0" />
<geometry>
<mesh filename="package://os_robots_description/meshes/base.stl"/>
</geometry>
<material name="base_material">
<color rgba="0.615686 0.811765 0.929412 1.0"/>
</material>
</visual>
<collision>
<origin xyz="0 0 0" rpy="0 -0 0" />
<geometry>
<mesh filename="package://os_robots_description/meshes/base.stl"/>
</geometry>
<material name="base_material">
<color rgba="0.615686 0.811765 0.929412 1.0"/>
</material>
</collision>
<inertial>
<origin xyz="7.89552e-05 9.80263e-05 0.0226173" rpy="0 0 0"/>
<mass value="1.3362" />
<inertia ixx="0.0017681" ixy="-3.16074e-09"  ixz="1.06737e-06" iyy="0.00216765" iyz="1.32518e-06" izz="0.00270499" />
</inertial>
</link>

<link name="link1">
<visual>
<origin xyz="0.06 -9.18485e-19 -0.025" rpy="0 -0 0" />
<geometry>
<mesh filename="package://os_robots_description/meshes/link1.stl"/>
</geometry>
<material name="link1_material">
<color rgba="0.615686 0.811765 0.929412 1.0"/>
</material>
</visual>
<collision>
<origin xyz="0.06 -9.18485e-19 -0.025" rpy="0 -0 0" />
<geometry>
<mesh filename="package://os_robots_description/meshes/link1.stl"/>
</geometry>
<material name="link1_material">
<color rgba="0.615686 0.811765 0.929412 1.0"/>
</material>
</collision>
<inertial>
<origin xyz="0.0637555 1.80092e-18 -0.0125" rpy="0 0 0"/>
<mass value="0.762287" />
<inertia ixx="0.000280019" ixy="0"  ixz="0" iyy="0.0025545" iyz="0" izz="0.00275511" />
</inertial>
</link>

<joint name="base" type="revolute">
<origin xyz="0 9.18485e-19 0.1" rpy="0 -0 0" />
<parent link="base" />
<child link="link1" />
<axis xyz="0 0 1"/>
<limit effort="1" velocity="20" lower="0" upper="3.14159"/>
<joint_properties friction="0.0"/>
</joint>


</robot>